{"nbformat":4,"nbformat_minor":0,"metadata":{"colab":{"provenance":[],"toc_visible":true,"authorship_tag":"ABX9TyNbvJjU6otIIxR4ACDHA+p/"},"kernelspec":{"name":"python3","display_name":"Python 3"},"language_info":{"name":"python"}},"cells":[{"cell_type":"markdown","source":["# **Python try...except Block**\n","The try...except block is used to handle exceptions in Python. Here's the syntax of try...except block:"],"metadata":{"id":"srQD1vysQ9gk"}},{"cell_type":"code","execution_count":null,"metadata":{"id":"xmpkCcrZETZn"},"outputs":[],"source":["try:\n","    # code that may cause exception\n","except:\n","    # code to run when exception occurs"]},{"cell_type":"code","source":["try:\n","    numerator = 10\n","    denominator = 0\n","\n","    result = numerator/denominator\n","\n","    print(result)\n","except:\n","    print(\"Error: Denominator cannot be 0.\")\n","\n"],"metadata":{"colab":{"base_uri":"https://localhost:8080/"},"id":"NlY3OcpMRB26","executionInfo":{"status":"ok","timestamp":1688900122719,"user_tz":-210,"elapsed":27,"user":{"displayName":"fatemeh makhloughi","userId":"01721314259232716745"}},"outputId":"bd21f1bf-bde3-4a4a-c664-7cf9be54e165"},"execution_count":1,"outputs":[{"output_type":"stream","name":"stdout","text":["Error: Denominator cannot be 0.\n"]}]},{"cell_type":"markdown","source":["# **Catching** Specific Exceptions in Python\n","For each try block, there can be zero or more except blocks. Multiple except blocks allow us to handle each exception differently.\n","\n","The argument type of each except block indicates the type of exception that can be handled by it. For example,"],"metadata":{"id":"H7L9kC1LRNO2"}},{"cell_type":"code","source":["try:\n","\n","    even_numbers = [2,4,6,8]\n","    print(even_numbers[5])\n","\n","except ZeroDivisionError:\n","    print(\"Denominator cannot be 0.\")\n","\n","except IndexError:\n","    print(\"Index Out of Bound.\")\n"],"metadata":{"colab":{"base_uri":"https://localhost:8080/"},"id":"vMrxJriBRQC3","executionInfo":{"status":"ok","timestamp":1688900143014,"user_tz":-210,"elapsed":9,"user":{"displayName":"fatemeh makhloughi","userId":"01721314259232716745"}},"outputId":"a07e13f6-988c-4f8b-a101-9e0c2d8f4656"},"execution_count":2,"outputs":[{"output_type":"stream","name":"stdout","text":["Index Out of Bound.\n"]}]},{"cell_type":"markdown","source":["# **Python try with else clause**"],"metadata":{"id":"i4gZWNmjS8gk"}},{"cell_type":"markdown","source":["In some situations, we might want to run a certain block of code if the code block inside try runs without any errors.\n","\n","For these cases, you can use the optional else keyword with the try statement.\n","\n","Let's look at an example:"],"metadata":{"id":"BxxcAfw5TAbV"}},{"cell_type":"code","source":["# program to print the reciprocal of even numbers\n","\n","try:\n","    num = int(input(\"Enter a number: \"))\n","    assert num % 2 == 0\n","except:\n","    print(\"Not an even number!\")\n","else:\n","    reciprocal = 1/num\n","    print(reciprocal)"],"metadata":{"colab":{"base_uri":"https://localhost:8080/"},"id":"laf2s1srS5uq","executionInfo":{"status":"ok","timestamp":1688900224238,"user_tz":-210,"elapsed":4070,"user":{"displayName":"fatemeh makhloughi","userId":"01721314259232716745"}},"outputId":"61e55b21-c23f-4ebe-bf28-70bb87bfe8ce"},"execution_count":3,"outputs":[{"output_type":"stream","name":"stdout","text":["Enter a number: 2\n","0.5\n"]}]},{"cell_type":"markdown","source":["# **Python try...finally**\n","In Python, the finally block is always executed no matter whether there is an exception or not.\n","\n","The finally block is optional. And, for each try block, there can be only one finally block.\n","\n","Let's see an example,"],"metadata":{"id":"EwIKgg0OTNNy"}},{"cell_type":"code","source":["try:\n","    numerator = 10\n","    denominator = 0\n","\n","    result = numerator/denominator\n","\n","    print(result)\n","except:\n","    print(\"Error: Denominator cannot be 0.\")\n","\n","finally:\n","    print(\"This is finally block.\")"],"metadata":{"colab":{"base_uri":"https://localhost:8080/"},"id":"TXSz4HCoTIBZ","executionInfo":{"status":"ok","timestamp":1688900350646,"user_tz":-210,"elapsed":1805,"user":{"displayName":"fatemeh makhloughi","userId":"01721314259232716745"}},"outputId":"d778f98c-34be-4b13-8d92-0066db895f9c"},"execution_count":4,"outputs":[{"output_type":"stream","name":"stdout","text":["Error: Denominator cannot be 0.\n","This is finally block.\n"]}]},{"cell_type":"markdown","source":["In the above example, we are dividing a number by 0 inside the try block. Here, this code generates an exception.\n","\n","The exception is caught by the except block. And, then the finally block is executed."],"metadata":{"id":"4fTt2LHyTbGt"}}]}